<?xml version="1.0"?>
<robot name="$(arg robot_name)">
  <link name="base_link"/>
  <link name="robot_body_link">
    <visual>
      <geometry>
        <box size="0.7 0.35 0.5"/>
      </geometry>
      <origin xyz="0 0 0" rpy="0 0 0"/>
      <material name="green">
        <color rgba="0 1 0 1"/>
      </material>
    </visual>
  </link>
  <link name="cart_rev_link">
    <visual>
      <geometry>
        <cylinder radius="0.03" length="0.15"/>
      </geometry>
      <origin xyz="0 0 0" rpy="0 0 0"/>
      <material name="black">
        <color rgba="0 0 0 1"/>
      </material>
    </visual>
  </link>
  <link name="cart_body_link">
    <visual>
      <geometry>
        <box size="0.64 0.49 0.12"/>
      </geometry>
      <origin xyz="0 0 0" rpy="0 0 0"/>
      <material name="yellow">
        <color rgba="1 1 0.2 1"/>
      </material>
    </visual>
  </link>
  <link name="front_lidar_link">
    <visual>
      <geometry>
        <cylinder radius="0.03" length="0.1"/>
      </geometry>
      <origin xyz="0 0 0" rpy="0 0 0"/>
      <material name="blue">
        <color rgba="0 0 1 1"/>
      </material>
    </visual>
  </link>
  <link name="rear_lidar_link">
    <visual>
      <geometry>
        <cylinder radius="0.03" length="0.1"/>
      </geometry>
      <origin xyz="0 0 0" rpy="0 0 0"/>
      <material name="blue">
        <color rgba="0 0 1 1"/>
      </material>
    </visual>
  </link>
  <joint name="robot_body_joint" type="fixed">
    <origin xyz="0 0 0" rpy="0 0 0"/>
    <parent link="base_link"/>
    <child link="robot_body_link"/>
  </joint>
  <joint name="cart_rev_joint" type="revolute">
    <origin xyz="-0.3 0 0.05" rpy="0 0 0"/>
    <axis xyz="0 0 1"/>
    <parent link="robot_body_link"/>
    <child link="cart_rev_link"/>
    <limit lower="${radians(-120)}" upper="${radians(120)}" effort="0" velocity="0"/>
  </joint>
  <joint name="cart_body_joint" type="fixed">
    <origin xyz="-0.54 0 -0.22" rpy="0 0 0"/>
    <parent link="cart_rev_link"/>
    <child link="cart_body_link"/>
  </joint>
  <joint name="front_lidar_joint" type="fixed">
    <origin xyz="0.25 0 0.1" rpy="0 0 0"/>
    <parent link="robot_body_link"/>
    <child link="front_lidar_link"/>
  </joint>
  <joint name="rear_lidar_joint" type="fixed">
    <origin xyz="-0.3 0 -0.14" rpy="${radians(180)} 0 ${radians(180)}"/>
    <parent link="robot_body_link"/>
    <child link="rear_lidar_link"/>
  </joint>
</robot>